<?xml version="1.0"?>

<robot name="raven" xmlns:xacro="http://ros.org/wiki/xacro">

  <!-- Start GZ or Ignition depending on ROS 2 Version -->
  <xacro:arg name="is_ignition" default="true"/>

  <!-- Load Simulated or Real Hardware Interfaces -->
  <xacro:arg name="is_sim" default="true"/>

  <!-- Include Gazebo Parameters -->
  <xacro:include filename="$(find raven_description)/urdf/raven_gazebo.xacro" />

  <!-- Include ros2_control Plugins -->
  <xacro:include filename="$(find raven_description)/urdf/raven_ros2_control.xacro" />


  <!-- MATERIAL COLOURS -->
  <material name = "grey">
    <color rgba="0.2 0.2 0.2 1"/>
  </material>

  <material name = "green">
    <color rgba="0 0.6 0 1"/>
  </material>

  <material name = "white">
    <color rgba="1 1 1 1"/>
  </material>

  <material name = "greyish">
    <color rgba="0.5 0.5 0.5 1"/>
  </material>


 <!-- LINKS -->

  <!-- MAIN LINK -->
  <link name="base_footprint"/>


  <!-- BASE PART -->
  <link name="base_link">
    <inertial>
      <origin xyz="0 0 0.04" rpy="0.0 0.25 0.3" />
      <mass value="8.2573504e-01"/>
      <inertia ixx="2.2124416e-02" ixy="-1.2294101e-04" ixz="3.4938785e-04"
               iyy="2.1193702e-02" iyz="-5.0120904e-05"
               izz="2.0064271e-02" />
    </inertial>
    <visual>
      <geometry>
        <box size="0.388 0.145 0.075"/>
      </geometry>
      <origin xyz="0 0 0" rpy="0 0 0"/>
      <material name="green"/>
    </visual>
    <collision>
      <geometry>
        <box size="0.388 0.145 0.075"/>
      </geometry>
      <origin xyz="0 0 0" rpy="0 0 0"/>
    </collision>
  </link>

  <joint name="base_joint" type="fixed">
    <parent link="base_footprint"/>
    <child link="base_link"/>
    <origin xyz="0 0 0.0905" rpy="0 0 0"/>    
  </joint>


  <!-- WHEEL LINK -->
  <link name="left_wheel_link">
    <inertial>
      <origin xyz="0 0 0" rpy="0 0 0" />
      <mass value="0.0530086043217644" />
      <inertia ixx="1.8792911368909E-05"  ixy="3.31256392204584E-10" ixz="-1.14082001662767E-08"
               iyy="3.11510738759073E-05" iyz="-3.60499245082192E-10"
               izz="1.88266886146847E-05" />
    </inertial>
    <visual>
      <geometry>
        <cylinder radius="0.0205" length="0.042"/>
      </geometry>
      <origin xyz="0 0 0" rpy="1.57 0 0"/>
      <material name="grey"/>
    </visual>
    <collision>
      <geometry>
        <cylinder radius="0.0205" length="0.042"/>
      </geometry>
      <origin xyz="0 0 0" rpy="1.57 0 0"/>
    </collision>
  </link>

  <joint name="wheel_left_joint" type="continuous">
    <parent link="base_link"/>
    <child link="left_wheel_link"/>
    <origin xyz="0 0.1035 -0.07" rpy="0 0 0"/>
    <axis xyz="0 1 0"/>
  </joint>


  <link name="right_wheel_link">
    <inertial>
      <origin xyz="0 0 0" rpy="0 0 0" />
      <mass value="0.0530086090966721" />
      <inertia ixx="1.88176298336665E-05" ixy="-4.8444933029987E-10" ixz="1.88163708851143E-08"
               iyy="3.11510738647764E-05" iyz="-6.93560663069607E-11"
               izz="1.8801969558182E-05" />
    </inertial>
    <visual>
      <geometry>
        <cylinder radius="0.0205" length="0.042"/>
      </geometry>
      <origin xyz="0 0 0" rpy="1.57 0 0"/>
      <material name="grey"/>
    </visual>
    <collision>
      <geometry>
        <cylinder radius="0.0205" length="0.042"/>
      </geometry>
      <origin xyz="0 0 0" rpy="1.57 0 0"/>
    </collision>
  </link>

  <joint name="wheel_right_joint" type="continuous">
    <parent link="base_link"/>
    <child link="right_wheel_link"/>
    <origin xyz="0 -0.1035 -0.07" rpy="0 0 0"/>
    <axis xyz="0 1 0"/>
  </joint>


  <!-- CASTOR WEEL -->
  <link name="back_support_link">
    <inertial>
      <origin xyz="3.8996812895542E-07 2.40073004698083E-07 0.00219173397061509" rpy="0 0 0" />
      <mass value="1.44379265037902E-06" />
      <inertia ixx="7.23075276010246E-11" ixy="-6.10956872363424E-16" ixz="2.22849693527207E-15"
               iyy="3.87137930859167E-11" iyz="2.939098587861E-15"
               izz="1.00967486676306E-10" />
    </inertial>
    <visual>
      <geometry>
        <sphere radius="0.053"/>
      </geometry>
      <origin xyz="0 0 0" rpy="1.57 0 0"/>
      <material name="greyish"/>
    </visual>
    <collision>
      <geometry>
        <sphere radius="0.053"/>
      </geometry>
      <origin xyz="0 0.058 0" rpy="1.57 0 0"/>
    </collision>
  </link>

  <joint name="base_back_support_joint" type="fixed">
    <parent link="base_link"/>
    <child link="back_support_link"/>
    <origin xyz="-0.14 0 -0.0375" rpy="0 0 0"/>
    <axis xyz="0 1 0"/>
  </joint>


  <link name="front_support_link">
    <inertial>
      <origin xyz="3.89968128948481E-07 2.40073004698083E-07 0.00219173397061506" rpy="0 0 0" />
      <mass value="1.44379265037903E-06" />
      <inertia ixx="7.23075276010246E-11" ixy="-6.10956883467859E-16" ixz="2.22849693525031E-15"
               iyy="3.8713793085917E-11"  iyz="2.93909858781952E-15"
               izz="1.00967486676306E-10" />
    </inertial>
    <visual>
      <geometry>
        <sphere radius="0.053"/>
      </geometry>
      <origin xyz="0 0 0" rpy="1.57 0 0"/>
      <material name="greyish"/>
    </visual>
    <collision>
      <geometry>
        <sphere radius="0.053"/>
      </geometry>
      <origin xyz="0 0 0" rpy="1.57 0 0"/>
    </collision>
  </link>

  <joint name="base_front_support_joint" type="fixed">
    <parent link="base_link"/>
    <child link="front_support_link"/>
    <origin xyz="0.14 0 -0.0375" rpy="0 0 0"/>
    <axis xyz="0 1 0"/>
  </joint>


  <!-- DEPTH CAMERA -->
  <link name="camera_link">
    <visual>
      <geometry>
        <box size="0.03 0.165 0.04"/>
      </geometry>
      <origin xyz="0 0 0" rpy="0 0 0"/>
      <material name="grey"/>
    </visual>
  </link>

  <joint name="camera_joint" type="fixed">
    <parent link="base_link"/>
    <child link="camera_link"/>
    <origin xyz="0.179 0 0.0645" rpy="0 0 0"/>
  </joint>


  <!-- LIDAR -->
  <link name="lidar_link">
    <visual>
      <geometry>
        <cylinder radius="0.026" length="0.0182"/>
      </geometry>
      <origin xyz="0 0 0" rpy="0 0 0"/>
      <material name="white"/>
    </visual>
  </link>

  <joint name="base_lidar_joint" type="fixed">
    <parent link="base_link"/>
    <child link="lidar_link"/>
    <origin xyz="0 0 0.1147" rpy="0 0 0"/>
  </joint>
 

  <!-- IMU -->
  <link name="imu_link">
    <inertial>
      <origin xyz="-0.00552433659106688 0.000168210391520346 0.000514000497342681" rpy="0 0 0" />
      <mass value="0.000528415362211671" />
      <inertia ixx="1.46176048428261E-08" ixy="1.40015117949421E-10" ixz="-1.99633872937403E-12"
               iyy="8.59662482954888E-09" iyz="7.52375112767959E-12"
               izz="2.30279421279312E-08" />
    </inertial>

    <visual>
      <origin xyz="0.0 0.0 0.0" rpy="0.0 0.0 0.0"/>
      <geometry>
        <mesh filename="package://raven_description/meshes/imu_link.STL"/>
      </geometry>      
    </visual>

    <collision>
      <origin xyz="0.0 0.0 0.0" rpy="0.0 0.0 0.0"/>
      <geometry>
        <mesh filename="package://raven_description/meshes/imu_link.STL"/>
      </geometry>  
    </collision>
  </link>

  <joint name="imu_joint" type="fixed">
    <parent link="base_link"/>
    <child link="imu_link"/>
    <origin xyz="0.0 0.0 0.0675" rpy="0.0 0.0 0.0"/>
  </joint>

</robot>